Workbook

Sheet delivery_main
A1: __row_index | B1: 膜类型 | C1: 样品编号 | D1: 膜材料 | E1: 制备方法 | F1: 水相单体 | G1: 水相单体浓度 | H1: 水相单体浓度_单位 | I1: 油相单体 | J1: 油相单体浓度 | K1: 油相单体浓度_单位 | L1: 有机溶剂 | M1: 基底 | N1: pH/碱度 | O1: pH/碱度_单位 | P1: 添加剂 | Q1: 添加剂浓度 | R1: 添加剂浓度_单位 | S1: 界面聚合时间 | T1: 界面聚合时间_单位 | U1: 反应温度 | V1: 反应温度_单位 | W1: 固化温度 | X1: 固化温度_单位 | Y1: 固化时间 | Z1: 固化时间_单位 | AA1: 改性剂 | AB1: 改性剂浓度 | AC1: 改性剂浓度_单位 | AD1: 改性时间 | AE1: 改性时间_单位 | AF1: 膜厚度 | AG1: 膜厚度_单位 | AH1: 粗糙度 | AI1: 粗糙度_单位 | AJ1: 交联度 | AK1: 交联度_单位 | AL1: 孔径 | AM1: 孔径_单位 | AN1: 表面官能团 | AO1: 表面Zeta电位 | AP1: 表面Zeta电位_单位 | AQ1: 接触角 | AR1: 接触角_单位 | AS1: 水通量 | AT1: 水通量_单位 | AU1: 盐截留 | AV1: 盐截留_单位 | AW1: 测试NaCl浓度 | AX1: 测试NaCl浓度_单位 | AY1: 通量衰减率 | AZ1: 通量衰减率_单位 | BA1: 测试压力 | BB1: 测试压力_单位 | BC1: 过滤模式 | BD1: 文件名称 | BE1: 发表年份 | BF1: DOI | BG1: 原始_溶质类型 | BH1: 标准_溶质类型 | BI1: 标准_性能数值 | BJ1: 标准_性能单位 | BK1: 性能数据类型 | BL1: 标准_IP时间(s) | BM1: 论文题目 | BN1: 水相单体_status | BO1: 油相单体_status | BP1: 添加剂_status | BQ1: 改性剂_status | BR1: 测试NaCl_status | BS1: 总review_count | BT1: 建议人工复核
A2: 0 | B2: RO | C2: PMA-GO/RO_Run3 | D2: PMA-GO modified Polyamide | E2: MA polymerization on GO functionalized RO membrane (Microwave-assisted) | F2: =IFERROR(TEXTJOIN("; ",TRUE,FILTER('concentration_review'!$Z$2:$Z$84,('concentration_review'!$A$2:$A$84=$A2)*('concentration_review'!$F$2:$F$84="水相单体"))),"") | G2: =IFERROR(TEXTJOIN("; ",TRUE,FILTER('concentration_review'!$AA$2:$AA$84,('concentration_review'!$A$2:$A$84=$A2)*('concentration_review'!$G$2:$G$84="水相单体浓度"))),"") | H2: =IFERROR(TEXTJOIN("; ",TRUE,FILTER('concentration_review'!$AB$2:$AB$84,('concentration_review'!$A$2:$A$84=$A2)*('concentration_review'!$G$2:$G$84="水相单体浓度_单位"))),"") | I2: =IFERROR(TEXTJOIN("; ",TRUE,FILTER('concentration_review'!$Z$2:$Z$84,('concentration_review'!$A$2:$A$84=$A2)*('concentration_review'!$F$2:$F$84="油相单体"))),"") | J2: =IFERROR(TEXTJOIN("; ",TRUE,FILTER('concentration_review'!$AA$2:$AA$84,('concentration_review'!$A$2:$A$84=$A2)*('concentration_review'!$G$2:$G$84="油相单体浓度"))),"") | K2: =IFERROR(TEXTJOIN("; ",TRUE,FILTER('concentration_review'!$AB$2:$AB$84,('concentration_review'!$A$2:$A$84=$A2)*('concentration_review'!$G$2:$G$84="油相单体浓度_单位"))),"") | M2: Polyamide/Polysulfone | P2: =IFERROR(TEXTJOIN("; ",TRUE,FILTER('concentration_review'!$Z$2:$Z$84,('concentration_review'!$A$2:$A$84=$A2)*('concentration_review'!$F$2:$F$84="添加剂"))),"") | Q2: =IFERROR(TEXTJOIN("; ",TRUE,FILTER('concentration_review'!$AA$2:$AA$84,('concentration_review'!$A$2:$A$84=$A2)*('concentration_review'!$G$2:$G$84="添加剂浓度"))),"") | R2: =IFERROR(TEXTJOIN("; ",TRUE,FILTER('concentration_review'!$AB$2:$AB$84,('concentration_review'!$A$2:$A$84=$A2)*('concentration_review'!$G$2:$G$84="添加剂浓度_单位"))),"") | S2: 9 | T2: s | W2: 70 | X2: ℃ | Y2: 5 | Z2: min | AA2: =IFERROR(TEXTJOIN("; ",TRUE,FILTER('concentration_review'!$Z$2:$Z$84,('concentration_review'!$A$2:$A$84=$A2)*('concentration_review'!$F$2:$F$84="改性剂"))),"") | AB2: =IFERROR(TEXTJOIN("; ",TRUE,FILTER('concentration_review'!$AA$2:$AA$84,('concentration_review'!$A$2:$A$84=$A2)*('concentration_review'!$G$2:$G$84="改性剂浓度"))),"") | AC2: =IFERROR(TEXTJOIN("; ",TRUE,FILTER('concentration_review'!$AB$2:$AB$84,('concentration_review'!$A$2:$A$84=$A2)*('concentration_review'!$G$2:$G$84="改性剂浓度_单位"))),"") | AH2: 44.77 | AI2: nm | AN2: C=O; -OH; C-H | AQ2: 18 | AR2: ° | AS2: 2.75 | AT2: L/(m²·h·bar) | AU2: 96.5 | AV2: % | AW2: =IFERROR(TEXTJOIN("; ",TRUE,FILTER('concentration_review'!$AA$2:$AA$84,('concentration_review'!$A$2:$A$84=$A2)*('concentration_review'!$G$2:$G$84="测试NaCl浓度"))),"") | AX2: =IFERROR(TEXTJOIN("; ",TRUE,FILTER('concentration_review'!$AB$2:$AB$84,('concentration_review'!$A$2:$A$84=$A2)*('concentration_review'!$G$2:$G$84="测试NaCl浓度_单位"))),"") | BA2: 25 | BB2: bar | BC2: Cross-flow | BD2: 10.1016_j.desal.2023.116372.pdf | BE2: 2023 | BF2: 10.1016/j.desal.2023.116372 | BG2: NaCl | BH2: NaCl | BI2: 0.11 | BJ2: L/(m²·h·bar) | BK2: 渗透系数(Permeance) | BL2: 9 | BM2: Effect of polymaleic acid and microwave radiations on reverse osmosis membrane's performance and properties: A response surface methodology approach | BN2: =IFERROR(TEXTJOIN("; ",TRUE,FILTER('concentration_review'!$AC$2:$AC$84,('concentration_review'!$A$2:$A$84=$A2)*('concentration_review'!$C$2:$C$84="aqueous_monomer"))),"") | BO2: =IFERROR(TEXTJOIN("; ",TRUE,FILTER('concentration_review'!$AC$2:$AC$84,('concentration_review'!$A$2:$A$84=$A2)*('concentration_review'!$C$2:$C$84="organic_monomer"))),"") | BP2: =IFERROR(TEXTJOIN("; ",TRUE,FILTER('concentration_review'!$AC$2:$AC$84,('concentration_review'!$A$2:$A$84=$A2)*('concentration_review'!$C$2:$C$84="additive"))),"") | BQ2: =IFERROR(TEXTJOIN("; ",TRUE,FILTER('concentration_review'!$AC$2:$AC$84,('concentration_review'!$A$2:$A$84=$A2)*('concentration_review'!$C$2:$C$84="modifier"))),"") | BR2: =IFERROR(TEXTJOIN("; ",TRUE,FILTER('concentration_review'!$AC$2:$AC$84,('concentration_review'!$A$2:$A$84=$A2)*('concentration_review'!$C$2:$C$84="test_nacl"))),"") | BS2: =SUMPRODUCT((--('concentration_review'!$A$2:$A$84=$A2))*('concentration_review'!$AE$2:$AE$84>0)) | BT2: =IF(=SUMPRODUCT((--('concentration_review'!$A$2:$A$84=$A2))*('concentration_review'!$AE$2:$AE$84>0))>0,1,0)
A3: 1 | B3: RO | C3: mm-BTEC | D3: Polyamide | E3: Interfacial polymerization (IP) | F3: =IFERROR(TEXTJOIN("; ",TRUE,FILTER('concentration_review'!$Z$2:$Z$84,('concentration_review'!$A$2:$A$84=$A3)*('concentration_review'!$F$2:$F$84="水相单体"))),"") | G3: =IFERROR(TEXTJOIN("; ",TRUE,FILTER('concentration_review'!$AA$2:$AA$84,('concentration_review'!$A$2:$A$84=$A3)*('concentration_review'!$G$2:$G$84="水相单体浓度"))),"") | H3: =IFERROR(TEXTJOIN("; ",TRUE,FILTER('concentration_review'!$AB$2:$AB$84,('concentration_review'!$A$2:$A$84=$A3)*('concentration_review'!$G$2:$G$84="水相单体浓度_单位"))),"") | I3: =IFERROR(TEXTJOIN("; ",TRUE,FILTER('concentration_review'!$Z$2:$Z$84,('concentration_review'!$A$2:$A$84=$A3)*('concentration_review'!$F$2:$F$84="油相单体"))),"") | J3: =IFERROR(TEXTJOIN("; ",TRUE,FILTER('concentration_review'!$AA$2:$AA$84,('concentration_review'!$A$2:$A$84=$A3)*('concentration_review'!$G$2:$G$84="油相单体浓度"))),"") | K3: =IFERROR(TEXTJOIN("; ",TRUE,FILTER('concentration_review'!$AB$2:$AB$84,('concentration_review'!$A$2:$A$84=$A3)*('concentration_review'!$G$2:$G$84="油相单体浓度_单位"))),"") | L3: Cyclohexane | M3: Polysulfone | N3: 10 | P3: =IFERROR(TEXTJOIN("; ",TRUE,FILTER('concentration_review'!$Z$2:$Z$84,('concentration_review'!$A$2:$A$84=$A3)*('concentration_review'!$F$2:$F$84="添加剂"))),"") | Q3: =IFERROR(TEXTJOIN("; ",TRUE,FILTER('concentration_review'!$AA$2:$AA$84,('concentration_review'!$A$2:$A$84=$A3)*('concentration_review'!$G$2:$G$84="添加剂浓度"))),"") | R3: =IFERROR(TEXTJOIN("; ",TRUE,FILTER('concentration_review'!$AB$2:$AB$84,('concentration_review'!$A$2:$A$84=$A3)*('concentration_review'!$G$2:$G$84="添加剂浓度_单位"))),"") | S3: 20 | T3: s | W3: 60 | X3: ℃ | AA3: =IFERROR(TEXTJOIN("; ",TRUE,FILTER('concentration_review'!$Z$2:$Z$84,('concentration_review'!$A$2:$A$84=$A3)*('concentration_review'!$F$2:$F$84="改性剂"))),"") | AB3: =IFERROR(TEXTJOIN("; ",TRUE,FILTER('concentration_review'!$AA$2:$AA$84,('concentration_review'!$A$2:$A$84=$A3)*('concentration_review'!$G$2:$G$84="改性剂浓度"))),"") | AC3: =IFERROR(TEXTJOIN("; ",TRUE,FILTER('concentration_review'!$AB$2:$AB$84,('concentration_review'!$A$2:$A$84=$A3)*('concentration_review'!$G$2:$G$84="改性剂浓度_单位"))),"") | AF3: 0.2 | AG3: µm | AH3: 147 | AI3: nm | AN3: '-NHCO-;-COOH | AQ3: 76 | AR3: ° | AS3: 31.7 | AT3: L/(m² h) | AU3: 98.4 | AV3: % | AW3: =IFERROR(TEXTJOIN("; ",TRUE,FILTER('concentration_review'!$AA$2:$AA$84,('concentration_review'!$A$2:$A$84=$A3)*('concentration_review'!$G$2:$G$84="测试NaCl浓度"))),"") | AX3: =IFERROR(TEXTJOIN("; ",TRUE,FILTER('concentration_review'!$AB$2:$AB$84,('concentration_review'!$A$2:$A$84=$A3)*('concentration_review'!$G$2:$G$84="测试NaCl浓度_单位"))),"") | BA3: 2 | BB3: MPa | BC3: Cross-flow | BD3: 10.1016_j.memsci.2008.02.022.pdf | BE3: 2008 | BF3: 10.1016/j.memsci.2008.02.022 | BG3: NaCl | BH3: NaCl | BI3: 1.585 | BJ3: L/(m²·h·bar) | BK3: 渗透系数(Permeance) | BL3: 20 | BM3: Polyamide thin film composite membranes prepared from isomeric biphenyl tetraacyl chloride and m-phenylenediamine | BN3: =IFERROR(TEXTJOIN("; ",TRUE,FILTER('concentration_review'!$AC$2:$AC$84,('concentration_review'!$A$2:$A$84=$A3)*('concentration_review'!$C$2:$C$84="aqueous_monomer"))),"") | BO3: =IFERROR(TEXTJOIN("; ",TRUE,FILTER('concentration_review'!$AC$2:$AC$84,('concentration_review'!$A$2:$A$84=$A3)*('concentration_review'!$C$2:$C$84="organic_monomer"))),"") | BP3: =IFERROR(TEXTJOIN("; ",TRUE,FILTER('concentration_review'!$AC$2:$AC$84,('concentration_review'!$A$2:$A$84=$A3)*('concentration_review'!$C$2:$C$84="additive"))),"") | BQ3: =IFERROR(TEXTJOIN("; ",TRUE,FILTER('concentration_review'!$AC$2:$AC$84,('concentration_review'!$A$2:$A$84=$A3)*('concentration_review'!$C$2:$C$84="modifier"))),"") | BR3: =IFERROR(TEXTJOIN("; ",TRUE,FILTER('concentration_review'!$AC$2:$AC$84,('concentration_review'!$A$2:$A$84=$A3)*('concentration_review'!$C$2:$C$84="test_nacl"))),"") | BS3: =SUMPRODUCT((--('concentration_review'!$A$2:$A$84=$A3))*('concentration_review'!$AE$2:$AE$84>0)) | BT3: =IF(=SUMPRODUCT((--('concentration_review'!$A$2:$A$84=$A3))*('concentration_review'!$AE$2:$AE$84>0))>0,1,0)
A4: 2 | B4: RO | C4: LIP 2 cycles | D4: Polyamide | E4: Layered interfacial polymerization | F4: =IFERROR(TEXTJOIN("; ",TRUE,FILTER('concentration_review'!$Z$2:$Z$84,('concentration_review'!$A$2:$A$84=$A4)*('concentration_review'!$F$2:$F$84="水相单体"))),"") | G4: =IFERROR(TEXTJOIN("; ",TRUE,FILTER('concentration_review'!$AA$2:$AA$84,('concentration_review'!$A$2:$A$84=$A4)*('concentration_review'!$G$2:$G$84="水相单体浓度"))),"") | H4: =IFERROR(TEXTJOIN("; ",TRUE,FILTER('concentration_review'!$AB$2:$AB$84,('concentration_review'!$A$2:$A$84=$A4)*('concentration_review'!$G$2:$G$84="水相单体浓度_单位"))),"") | I4: =IFERROR(TEXTJOIN("; ",TRUE,FILTER('concentration_review'!$Z$2:$Z$84,('concentration_review'!$A$2:$A$84=$A4)*('concentration_review'!$F$2:$F$84="油相单体"))),"") | J4: =IFERROR(TEXTJOIN("; ",TRUE,FILTER('concentration_review'!$AA$2:$AA$84,('concentration_review'!$A$2:$A$84=$A4)*('concentration_review'!$G$2:$G$84="油相单体浓度"))),"") | K4: =IFERROR(TEXTJOIN("; ",TRUE,FILTER('concentration_review'!$AB$2:$AB$84,('concentration_review'!$A$2:$A$84=$A4)*('concentration_review'!$G$2:$G$84="油相单体浓度_单位"))),"") | L4: n-hexane | M4: Hydrolyzed PAN with PEI/PAA interlayer | P4: =IFERROR(TEXTJOIN("; ",TRUE,FILTER('concentration_review'!$Z$2:$Z$84,('concentration_review'!$A$2:$A$84=$A4)*('concentration_review'!$F$2:$F$84="添加剂"))),"") | Q4: =IFERROR(TEXTJOIN("; ",TRUE,FILTER('concentration_review'!$AA$2:$AA$84,('concentration_review'!$A$2:$A$84=$A4)*('concentration_review'!$G$2:$G$84="添加剂浓度"))),"") | R4: =IFERROR(TEXTJOIN("; ",TRUE,FILTER('concentration_review'!$AB$2:$AB$84,('concentration_review'!$A$2:$A$84=$A4)*('concentration_review'!$G$2:$G$84="添加剂浓度_单位"))),"") | S4: 1 | T4: min | W4: 70 | X4: ℃ | Y4: 2 | Z4: min | AA4: =IFERROR(TEXTJOIN("; ",TRUE,FILTER('concentration_review'!$Z$2:$Z$84,('concentration_review'!$A$2:$A$84=$A4)*('concentration_review'!$F$2:$F$84="改性剂"))),"") | AB4: =IFERROR(TEXTJOIN("; ",TRUE,FILTER('concentration_review'!$AA$2:$AA$84,('concentration_review'!$A$2:$A$84=$A4)*('concentration_review'!$G$2:$G$84="改性剂浓度"))),"") | AC4: =IFERROR(TEXTJOIN("; ",TRUE,FILTER('concentration_review'!$AB$2:$AB$84,('concentration_review'!$A$2:$A$84=$A4)*('concentration_review'!$G$2:$G$84="改性剂浓度_单位"))),"") | AF4: ~21 | AG4: nm | AH4: ~6 | AI4: nm | AN4: C=O;N-H | AS4: 1.34 | AT4: L m⁻² h⁻¹ bar⁻¹ | AU4: 99 | AV4: % | AW4: =IFERROR(TEXTJOIN("; ",TRUE,FILTER('concentration_review'!$AA$2:$AA$84,('concentration_review'!$A$2:$A$84=$A4)*('concentration_review'!$G$2:$G$84="测试NaCl浓度"))),"") | AX4: =IFERROR(TEXTJOIN("; ",TRUE,FILTER('concentration_review'!$AB$2:$AB$84,('concentration_review'!$A$2:$A$84=$A4)*('concentration_review'!$G$2:$G$84="测试NaCl浓度_单位"))),"") | BA4: 15.5 | BB4: bar | BC4: Cross-flow | BD4: 10.1016_j.memsci.2016.12.066.pdf | BE4: 2017 | BF4: 10.1016/j.memsci.2016.12.066 | BG4: NaCl | BH4: NaCl | BI4: 0.0865 | BJ4: L/(m²·h·bar) | BK4: 渗透系数(Permeance) | BL4: 60 | BM4: Thin film composite reverse osmosis membranes prepared via layered interfacial polymerization | BN4: =IFERROR(TEXTJOIN("; ",TRUE,FILTER('concentration_review'!$AC$2:$AC$84,('concentration_review'!$A$2:$A$84=$A4)*('concentration_review'!$C$2:$C$84="aqueous_monomer"))),"") | BO4: =IFERROR(TEXTJOIN("; ",TRUE,FILTER('concentration_review'!$AC$2:$AC$84,('concentration_review'!$A$2:$A$84=$A4)*('concentration_review'!$C$2:$C$84="organic_monomer"))),"") | BP4: =IFERROR(TEXTJOIN("; ",TRUE,FILTER('concentration_review'!$AC$2:$AC$84,('concentration_review'!$A$2:$A$84=$A4)*('concentration_review'!$C$2:$C$84="additive"))),"") | BQ4: =IFERROR(TEXTJOIN("; ",TRUE,FILTER('concentration_review'!$AC$2:$AC$84,('concentration_review'!$A$2:$A$84=$A4)*('concentration_review'!$C$2:$C$84="modifier"))),"") | BR4: =IFERROR(TEXTJOIN("; ",TRUE,FILTER('concentration_review'!$AC$2:$AC$84,('concentration_review'!$A$2:$A$84=$A4)*('concentration_review'!$C$2:$C$84="test_nacl"))),"") | BS4: =SUMPRODUCT((--('concentration_review'!$A$2:$A$84=$A4))*('concentration_review'!$AE$2:$AE$84>0)) | BT4: =IF(=SUMPRODUCT((--('concentration_review'!$A$2:$A$84=$A4))*('concentration_review'!$AE$2:$AE$84>0))>0,1,0)
A5: 3 | B5: RO | C5: LIP 0 cycle | D5: PEI/PAA | E5: Polyelectrolyte multilayer deposition on hydrolyzed PAN | F5: =IFERROR(TEXTJOIN("; ",TRUE,FILTER('concentration_review'!$Z$2:$Z$84,('concentration_review'!$A$2:$A$84=$A5)*('concentration_review'!$F$2:$F$84="水相单体"))),"") | G5: =IFERROR(TEXTJOIN("; ",TRUE,FILTER('concentration_review'!$AA$2:$AA$84,('concentration_review'!$A$2:$A$84=$A5)*('concentration_review'!$G$2:$G$84="水相单体浓度"))),"") | H5: =IFERROR(TEXTJOIN("; ",TRUE,FILTER('concentration_review'!$AB$2:$AB$84,('concentration_review'!$A$2:$A$84=$A5)*('concentration_review'!$G$2:$G$84="水相单体浓度_单位"))),"") | I5: =IFERROR(TEXTJOIN("; ",TRUE,FILTER('concentration_review'!$Z$2:$Z$84,('concentration_review'!$A$2:$A$84=$A5)*('concentration_review'!$F$2:$F$84="油相单体"))),"") | J5: =IFERROR(TEXTJOIN("; ",TRUE,FILTER('concentration_review'!$AA$2:$AA$84,('concentration_review'!$A$2:$A$84=$A5)*('concentration_review'!$G$2:$G$84="油相单体浓度"))),"") | K5: =IFERROR(TEXTJOIN("; ",TRUE,FILTER('concentration_review'!$AB$2:$AB$84,('concentration_review'!$A$2:$A$84=$A5)*('concentration_review'!$G$2:$G$84="油相单体浓度_单位"))),"") | M5: Hydrolyzed PAN | P5: =IFERROR(TEXTJOIN("; ",TRUE,FILTER('concentration_review'!$Z$2:$Z$84,('concentration_review'!$A$2:$A$84=$A5)*('concentration_review'!$F$2:$F$84="添加剂"))),"") | Q5: =IFERROR(TEXTJOIN("; ",TRUE,FILTER('concentration_review'!$AA$2:$AA$84,('concentration_review'!$A$2:$A$84=$A5)*('concentration_review'!$G$2:$G$84="添加剂浓度"))),"") | R5: =IFERROR(TEXTJOIN("; ",TRUE,FILTER('concentration_review'!$AB$2:$AB$84,('concentration_review'!$A$2:$A$84=$A5)*('concentration_review'!$G$2:$G$84="添加剂浓度_单位"))),"") | AA5: =IFERROR(TEXTJOIN("; ",TRUE,FILTER('concentration_review'!$Z$2:$Z$84,('concentration_review'!$A$2:$A$84=$A5)*('concentration_review'!$F$2:$F$84="改性剂"))),"") | AB5: =IFERROR(TEXTJOIN("; ",TRUE,FILTER('concentration_review'!$AA$2:$AA$84,('concentration_review'!$A$2:$A$84=$A5)*('concentration_review'!$G$2:$G$84="改性剂浓度"))),"") | AC5: =IFERROR(TEXTJOIN("; ",TRUE,FILTER('concentration_review'!$AB$2:$AB$84,('concentration_review'!$A$2:$A$84=$A5)*('concentration_review'!$G$2:$G$84="改性剂浓度_单位"))),"") | AD5: 15;10 | AE5: min;min | AH5: ~8.5 | AI5: nm | AS5: 7.23 | AT5: L m⁻² h⁻¹ bar⁻¹ | AU5: 33.3 | AV5: % | AW5: =IFERROR(TEXTJOIN("; ",TRUE,FILTER('concentration_review'!$AA$2:$AA$84,('concentration_review'!$A$2:$A$84=$A5)*('concentration_review'!$G$2:$G$84="测试NaCl浓度"))),"") | AX5: =IFERROR(TEXTJOIN("; ",TRUE,FILTER('concentration_review'!$AB$2:$AB$84,('concentration_review'!$A$2:$A$84=$A5)*('concentration_review'!$G$2:$G$84="测试NaCl浓度_单位"))),"") | BA5: 15.5 | BB5: bar | BC5: Cross-flow | BD5: 10.1016_j.memsci.2016.12.066.pdf | BE5: 2017 | BF5: 10.1016/j.memsci.2016.12.066 | BG5: NaCl | BH5: NaCl | BI5: 0.4665 | BJ5: L/(m²·h·bar) | BK5: 渗透系数(Permeance) | BM5: Thin film composite reverse osmosis membranes prepared via layered interfacial polymerization | BN5: =IFERROR(TEXTJOIN("; ",TRUE,FILTER('concentration_review'!$AC$2:$AC$84,('concentration_review'!$A$2:$A$84=$A5)*('concentration_review'!$C$2:$C$84="aqueous_monomer"))),"") | BO5: =IFERROR(TEXTJOIN("; ",TRUE,FILTER('concentration_review'!$AC$2:$AC$84,('concentration_review'!$A$2:$A$84=$A5)*('concentration_review'!$C$2:$C$84="organic_monomer"))),"") | BP5: =IFERROR(TEXTJOIN("; ",TRUE,FILTER('concentration_review'!$AC$2:$AC$84,('concentration_review'!$A$2:$A$84=$A5)*('concentration_review'!$C$2:$C$84="additive"))),"") | BQ5: =IFERROR(TEXTJOIN("; ",TRUE,FILTER('concentration_review'!$AC$2:$AC$84,('concentration_review'!$A$2:$A$84=$A5)*('concentration_review'!$C$2:$C$84="modifier"))),"") | BR5: =IFERROR(TEXTJOIN("; ",TRUE,FILTER('concentration_review'!$AC$2:$AC$84,('concentration_review'!$A$2:$A$84=$A5)*('concentration_review'!$C$2:$C$84="test_nacl"))),"") | BS5: =SUMPRODUCT((--('concentration_review'!$A$2:$A$84=$A5))*('concentration_review'!$AE$2:$AE$84>0)) | BT5: =IF(=SUMPRODUCT((--('concentration_review'!$A$2:$A$84=$A5))*('concentration_review'!$AE$2:$AE$84>0))>0,1,0)
A6: 4 | B6: RO | C6: PSf/TA-RO-1.0DMC | D6: Polyamide | E6: Interfacial polymerization (IP) | F6: =IFERROR(TEXTJOIN("; ",TRUE,FILTER('concentration_review'!$Z$2:$Z$84,('concentration_review'!$A$2:$A$84=$A6)*('concentration_review'!$F$2:$F$84="水相单体"))),"") | G6: =IFERROR(TEXTJOIN("; ",TRUE,FILTER('concentration_review'!$AA$2:$AA$84,('concentration_review'!$A$2:$A$84=$A6)*('concentration_review'!$G$2:$G$84="水相单体浓度"))),"") | H6: =IFERROR(TEXTJOIN("; ",TRUE,FILTER('concentration_review'!$AB$2:$AB$84,('concentration_review'!$A$2:$A$84=$A6)*('concentration_review'!$G$2:$G$84="水相单体浓度_单位"))),"") | I6: =IFERROR(TEXTJOIN("; ",TRUE,FILTER('concentration_review'!$Z$2:$Z$84,('concentration_review'!$A$2:$A$84=$A6)*('concentration_review'!$F$2:$F$84="油相单体"))),"") | J6: =IFERROR(TEXTJOIN("; ",TRUE,FILTER('concentration_review'!$AA$2:$AA$84,('concentration_review'!$A$2:$A$84=$A6)*('concentration_review'!$G$2:$G$84="油相单体浓度"))),"") | K6: =IFERROR(TEXTJOIN("; ",TRUE,FILTER('concentration_review'!$AB$2:$AB$84,('concentration_review'!$A$2:$A$84=$A6)*('concentration_review'!$G$2:$G$84="油相单体浓度_单位"))),"") | L6: Heptane; DMC | M6: PSf | P6: =IFERROR(TEXTJOIN("; ",TRUE,FILTER('concentration_review'!$Z$2:$Z$84,('concentration_review'!$A$2:$A$84=$A6)*('concentration_review'!$F$2:$F$84="添加剂"))),"") | Q6: =IFERROR(TEXTJOIN("; ",TRUE,FILTER('concentration_review'!$AA$2:$AA$84,('concentration_review'!$A$2:$A$84=$A6)*('concentration_review'!$G$2:$G$84="添加剂浓度"))),"") | R6: =IFERROR(TEXTJOIN("; ",TRUE,FILTER('concentration_review'!$AB$2:$AB$84,('concentration_review'!$A$2:$A$84=$A6)*('concentration_review'!$G$2:$G$84="添加剂浓度_单位"))),"") | S6: 30 | T6: s | W6: 80 | X6: ℃ | Y6: 5 | Z6: min | AA6: =IFERROR(TEXTJOIN("; ",TRUE,FILTER('concentration_review'!$Z$2:$Z$84,('concentration_review'!$A$2:$A$84=$A6)*('concentration_review'!$F$2:$F$84="改性剂"))),"") | AB6: =IFERROR(TEXTJOIN("; ",TRUE,FILTER('concentration_review'!$AA$2:$AA$84,('concentration_review'!$A$2:$A$84=$A6)*('concentration_review'!$G$2:$G$84="改性剂浓度"))),"") | AC6: =IFERROR(TEXTJOIN("; ",TRUE,FILTER('concentration_review'!$AB$2:$AB$84,('concentration_review'!$A$2:$A$84=$A6)*('concentration_review'!$G$2:$G$84="改性剂浓度_单位"))),"") | AS6: 50 | AT6: L/(m²·h) | AU6: 99 | AV6: % | AW6: =IFERROR(TEXTJOIN("; ",TRUE,FILTER('concentration_review'!$AA$2:$AA$84,('concentration_review'!$A$2:$A$84=$A6)*('concentration_review'!$G$2:$G$84="测试NaCl浓度"))),"") | AX6: =IFERROR(TEXTJOIN("; ",TRUE,FILTER('concentration_review'!$AB$2:$AB$84,('concentration_review'!$A$2:$A$84=$A6)*('concentration_review'!$G$2:$G$84="测试NaCl浓度_单位"))),"") | BA6: 15.5 | BB6: bar | BC6: Cross-flow | BD6: 10.1016_j.memsci.2019.117474.pdf | BE6: 2020 | BF6: 10.1016/j.memsci.2019.117474 | BG6: NaCl | BH6: NaCl | BI6: 3.2258 | BJ6: L/(m²·h·bar) | BK6: 渗透系数(Permeance) | BL6: 30 | BM6: Combining tannic acid-modified support and a green co-solvent for high performance reverse osmosis membranes | BN6: =IFERROR(TEXTJOIN("; ",TRUE,FILTER('concentration_review'!$AC$2:$AC$84,('concentration_review'!$A$2:$A$84=$A6)*('concentration_review'!$C$2:$C$84="aqueous_monomer"))),"") | BO6: =IFERROR(TEXTJOIN("; ",TRUE,FILTER('concentration_review'!$AC$2:$AC$84,('concentration_review'!$A$2:$A$84=$A6)*('concentration_review'!$C$2:$C$84="organic_monomer"))),"") | BP6: =IFERROR(TEXTJOIN("; ",TRUE,FILTER('concentration_review'!$AC$2:$AC$84,('concentration_review'!$A$2:$A$84=$A6)*('concentration_review'!$C$2:$C$84="additive"))),"") | BQ6: =IFERROR(TEXTJOIN("; ",TRUE,FILTER('concentration_review'!$AC$2:$AC$84,('concentration_review'!$A$2:$A$84=$A6)*('concentration_review'!$C$2:$C$84="modifier"))),"") | BR6: =IFERROR(TEXTJOIN("; ",TRUE,FILTER('concentration_review'!$AC$2:$AC$84,('concentration_review'!$A$2:$A$84=$A6)*('concentration_review'!$C$2:$C$84="test_nacl"))),"") | BS6: =SUMPRODUCT((--('concentration_review'!$A$2:$A$84=$A6))*('concentration_review'!$AE$2:$AE$84>0)) | BT6: =IF(=SUMPRODUCT((--('concentration_review'!$A$2:$A$84=$A6))*('concentration_review'!$AE$2:$AE$84>0))>0,1,0)
A7: 5 | B7: RO | C7: MDOPC/OG | D7: Polyamide | E7: Interfacial polymerization (IP) | F7: =IFERROR(TEXTJOIN("; ",TRUE,FILTER('concentration_review'!$Z$2:$Z$84,('concentration_review'!$A$2:$A$84=$A7)*('concentration_review'!$F$2:$F$84="水相单体"))),"") | G7: =IFERROR(TEXTJOIN("; ",TRUE,FILTER('concentration_review'!$AA$2:$AA$84,('concentration_review'!$A$2:$A$84=$A7)*('concentration_review'!$G$2:$G$84="水相单体浓度"))),"") | H7: =IFERROR(TEXTJOIN("; ",TRUE,FILTER('concentration_review'!$AB$2:$AB$84,('concentration_review'!$A$2:$A$84=$A7)*('concentration_review'!$G$2:$G$84="水相单体浓度_单位"))),"") | I7: =IFERROR(TEXTJOIN("; ",TRUE,FILTER('concentration_review'!$Z$2:$Z$84,('concentration_review'!$A$2:$A$84=$A7)*('concentration_review'!$F$2:$F$84="油相单体"))),"") | J7: =IFERROR(TEXTJOIN("; ",TRUE,FILTER('concentration_review'!$AA$2:$AA$84,('concentration_review'!$A$2:$A$84=$A7)*('concentration_review'!$G$2:$G$84="油相单体浓度"))),"") | K7: =IFERROR(TEXTJOIN("; ",TRUE,FILTER('concentration_review'!$AB$2:$AB$84,('concentration_review'!$A$2:$A$84=$A7)*('concentration_review'!$G$2:$G$84="油相单体浓度_单位"))),"") | L7: Isopar G | M7: PSF | P7: =IFERROR(TEXTJOIN("; ",TRUE,FILTER('concentration_review'!$Z$2:$Z$84,('concentration_review'!$A$2:$A$84=$A7)*('concentration_review'!$F$2:$F$84="添加剂"))),"") | Q7: =IFERROR(TEXTJOIN("; ",TRUE,FILTER('concentration_review'!$AA$2:$AA$84,('concentration_review'!$A$2:$A$84=$A7)*('concentration_review'!$G$2:$G$84="添加剂浓度"))),"") | R7: =IFERROR(TEXTJOIN("; ",TRUE,FILTER('concentration_review'!$AB$2:$AB$84,('concentration_review'!$A$2:$A$84=$A7)*('concentration_review'!$G$2:$G$84="添加剂浓度_单位"))),"") | S7: 1 | T7: min | W7: 90 | X7: ℃ | Y7: 6 | Z7: min | AA7: =IFERROR(TEXTJOIN("; ",TRUE,FILTER('concentration_review'!$Z$2:$Z$84,('concentration_review'!$A$2:$A$84=$A7)*('concentration_review'!$F$2:$F$84="改性剂"))),"") | AB7: =IFERROR(TEXTJOIN("; ",TRUE,FILTER('concentration_review'!$AA$2:$AA$84,('concentration_review'!$A$2:$A$84=$A7)*('concentration_review'!$G$2:$G$84="改性剂浓度"))),"") | AC7: =IFERROR(TEXTJOIN("; ",TRUE,FILTER('concentration_review'!$AB$2:$AB$84,('concentration_review'!$A$2:$A$84=$A7)*('concentration_review'!$G$2:$G$84="改性剂浓度_单位"))),"") | AF7: 262 | AG7: nm | AH7: 2.26 | AS7: 2.4 | AT7: L/(m²·h·bar) | AU7: 99 | AV7: % | AW7: =IFERROR(TEXTJOIN("; ",TRUE,FILTER('concentration_review'!$AA$2:$AA$84,('concentration_review'!$A$2:$A$84=$A7)*('concentration_review'!$G$2:$G$84="测试NaCl浓度"))),"") | AX7: =IFERROR(TEXTJOIN("; ",TRUE,FILTER('concentration_review'!$AB$2:$AB$84,('concentration_review'!$A$2:$A$84=$A7)*('concentration_review'!$G$2:$G$84="测试NaCl浓度_单位"))),"") | BA7: 50 | BB7: bar | BC7: Cross-flow | BD7: 10.1021_acs.est.1c08857.pdf | BE7: 2022 | BF7: 10.1021/acs.est.1c08857 | BG7: NaCl | BH7: NaCl | BI7: 0.048 | BJ7: L/(m²·h·bar) | BK7: 渗透系数(Permeance) | BL7: 60 | BM7: Proteoliposome-Incorporated Seawater Reverse Osmosis Polyamide Membrane: Is the Aquaporin Water Channel Effect in Improving Membrane Performance Overestimated? | BN7: =IFERROR(TEXTJOIN("; ",TRUE,FILTER('concentration_review'!$AC$2:$AC$84,('concentration_review'!$A$2:$A$84=$A7)*('concentration_review'!$C$2:$C$84="aqueous_monomer"))),"") | BO7: =IFERROR(TEXTJOIN("; ",TRUE,FILTER('concentration_review'!$AC$2:$AC$84,('concentration_review'!$A$2:$A$84=$A7)*('concentration_review'!$C$2:$C$84="organic_monomer"))),"") | BP7: =IFERROR(TEXTJOIN("; ",TRUE,FILTER('concentration_review'!$AC$2:$AC$84,('concentration_review'!$A$2:$A$84=$A7)*('concentration_review'!$C$2:$C$84="additive"))),"") | BQ7: =IFERROR(TEXTJOIN("; ",TRUE,FILTER('concentration_review'!$AC$2:$AC$84,('concentration_review'!$A$2:$A$84=$A7)*('concentration_review'!$C$2:$C$84="modifier"))),"") | BR7: =IFERROR(TEXTJOIN("; ",TRUE,FILTER('concentration_review'!$AC$2:$AC$84,('concentration_review'!$A$2:$A$84=$A7)*('concentration_review'!$C$2:$C$84="test_nacl"))),"") | BS7: =SUMPRODUCT((--('concentration_review'!$A$2:$A$84=$A7))*('concentration_review'!$AE$2:$AE$84>0)) | BT7: =IF(=SUMPRODUCT((--('concentration_review'!$A$2:$A$84=$A7))*('concentration_review'!$AE$2:$AE$84>0))>0,1,0)
A8: 6 | B8: RO | C8: TFC-toluene | D8: Polyamide | E8: Interfacial polymerization (IP) | F8: =IFERROR(TEXTJOIN("; ",TRUE,FILTER('concentration_review'!$Z$2:$Z$84,('concentration_review'!$A$2:$A$84=$A8)*('concentration_review'!$F$2:$F$84="水相单体"))),"") | G8: =IFERROR(TEXTJOIN("; ",TRUE,FILTER('concentration_review'!$AA$2:$AA$84,('concentration_review'!$A$2:$A$84=$A8)*('concentration_review'!$G$2:$G$84="水相单体浓度"))),"") | H8: =IFERROR(TEXTJOIN("; ",TRUE,FILTER('concentration_review'!$AB$2:$AB$84,('concentration_review'!$A$2:$A$84=$A8)*('concentration_review'!$G$2:$G$84="水相单体浓度_单位"))),"") | I8: =IFERROR(TEXTJOIN("; ",TRUE,FILTER('concentration_review'!$Z$2:$Z$84,('concentration_review'!$A$2:$A$84=$A8)*('concentration_review'!$F$2:$F$84="油相单体"))),"") | J8: =IFERROR(TEXTJOIN("; ",TRUE,FILTER('concentration_review'!$AA$2:$AA$84,('concentration_review'!$A$2:$A$84=$A8)*('concentration_review'!$G$2:$G$84="油相单体浓度"))),"") | K8: =IFERROR(TEXTJOIN("; ",TRUE,FILTER('concentration_review'!$AB$2:$AB$84,('concentration_review'!$A$2:$A$84=$A8)*('concentration_review'!$G$2:$G$84="油相单体浓度_单位"))),"") | L8: n-hexane | M8: PSf | P8: =IFERROR(TEXTJOIN("; ",TRUE,FILTER('concentration_review'!$Z$2:$Z$84,('concentration_review'!$A$2:$A$84=$A8)*('concentration_review'!$F$2:$F$84="添加剂"))),"") | Q8: =IFERROR(TEXTJOIN("; ",TRUE,FILTER('concentration_review'!$AA$2:$AA$84,('concentration_review'!$A$2:$A$84=$A8)*('concentration_review'!$G$2:$G$84="添加剂浓度"))),"") | R8: =IFERROR(TEXTJOIN("; ",TRUE,FILTER('concentration_review'!$AB$2:$AB$84,('concentration_review'!$A$2:$A$84=$A8)*('concentration_review'!$G$2:$G$84="添加剂浓度_单位"))),"") | S8: 1 | T8: min | U8: ~25 | V8: °C | W8: 50 | X8: °C | Y8: 10 | Z8: min | AA8: =IFERROR(TEXTJOIN("; ",TRUE,FILTER('concentration_review'!$Z$2:$Z$84,('concentration_review'!$A$2:$A$84=$A8)*('concentration_review'!$F$2:$F$84="改性剂"))),"") | AB8: =IFERROR(TEXTJOIN("; ",TRUE,FILTER('concentration_review'!$AA$2:$AA$84,('concentration_review'!$A$2:$A$84=$A8)*('concentration_review'!$G$2:$G$84="改性剂浓度"))),"") | AC8: =IFERROR(TEXTJOIN("; ",TRUE,FILTER('concentration_review'!$AB$2:$AB$84,('concentration_review'!$A$2:$A$84=$A8)*('concentration_review'!$G$2:$G$84="改性剂浓度_单位"))),"") | AF8: 248 | AG8: nm | AH8: 61.5 | AI8: nm | AL8: 0.06 | AM8: Void fraction | AO8: -32.3 | AP8: mV | AQ8: 72.4 | AR8: ° | AS8: 1.89 | AT8: L/(m²·h·bar) | AU8: 99.3 | AV8: % | AW8: =IFERROR(TEXTJOIN("; ",TRUE,FILTER('concentration_review'!$AA$2:$AA$84,('concentration_review'!$A$2:$A$84=$A8)*('concentration_review'!$G$2:$G$84="测试NaCl浓度"))),"") | AX8: =IFERROR(TEXTJOIN("; ",TRUE,FILTER('concentration_review'!$AB$2:$AB$84,('concentration_review'!$A$2:$A$84=$A8)*('concentration_review'!$G$2:$G$84="测试NaCl浓度_单位"))),"") | BA8: 15.5 | BB8: bar | BC8: Cross-flow | BD8: 10.1021_acs.est.2c01140.pdf | BE8: 2022 | BF8: 10.1021/acs.est.2c01140 | BG8: NaCl | BH8: NaCl | BI8: 0.1219 | BJ8: L/(m²·h·bar) | BK8: 渗透系数(Permeance) | BL8: 60 | BM8: Cosolvent-Assisted Interfacial Polymerization toward Regulating the Morphology and Performance of Polyamide Reverse Osmosis Membranes: Increased m-Phenylenediamine Solubility or Enhanced Interfacial Vaporization? | BN8: =IFERROR(TEXTJOIN("; ",TRUE,FILTER('concentration_review'!$AC$2:$AC$84,('concentration_review'!$A$2:$A$84=$A8)*('concentration_review'!$C$2:$C$84="aqueous_monomer"))),"") | BO8: =IFERROR(TEXTJOIN("; ",TRUE,FILTER('concentration_review'!$AC$2:$AC$84,('concentration_review'!$A$2:$A$84=$A8)*('concentration_review'!$C$2:$C$84="organic_monomer"))),"") | BP8: =IFERROR(TEXTJOIN("; ",TRUE,FILTER('concentration_review'!$AC$2:$AC$84,('concentration_review'!$A$2:$A$84=$A8)*('concentration_review'!$C$2:$C$84="additive"))),"") | BQ8: =IFERROR(TEXTJOIN("; ",TRUE,FILTER('concentration_review'!$AC$2:$AC$84,('concentration_review'!$A$2:$A$84=$A8)*('concentration_review'!$C$2:$C$84="modifier"))),"") | BR8: =IFERROR(TEXTJOIN("; ",TRUE,FILTER('concentration_review'!$AC$2:$AC$84,('concentration_review'!$A$2:$A$84=$A8)*('concentration_review'!$C$2:$C$84="test_nacl"))),"") | BS8: =SUMPRODUCT((--('concentration_review'!$A$2:$A$84=$A8))*('concentration_review'!$AE$2:$AE$84>0)) | BT8: =IF(=SUMPRODUCT((--('concentration_review'!$A$2:$A$84=$A8))*('concentration_review'!$AE$2:$AE$84>0))>0,1,0)
A9: 7 | B9: NF; RO | C9: PVA-PVS-Stirred-NaCl-10mM-5bar | D9: Polyelectrolyte (PVA/PVS) | E9: Layer-by-Layer Assembly | F9: =IFERROR(TEXTJOIN("; ",TRUE,FILTER('concentration_review'!$Z$2:$Z$84,('concentration_review'!$A$2:$A$84=$A9)*('concentration_review'!$F$2:$F$84="水相单体"))),"") | G9: =IFERROR(TEXTJOIN("; ",TRUE,FILTER('concentration_review'!$AA$2:$AA$84,('concentration_review'!$A$2:$A$84=$A9)*('concentration_review'!$G$2:$G$84="水相单体浓度"))),"") | H9: =IFERROR(TEXTJOIN("; ",TRUE,FILTER('concentration_review'!$AB$2:$AB$84,('concentration_review'!$A$2:$A$84=$A9)*('concentration_review'!$G$2:$G$84="水相单体浓度_单位"))),"") | I9: =IFERROR(TEXTJOIN("; ",TRUE,FILTER('concentration_review'!$Z$2:$Z$84,('concentration_review'!$A$2:$A$84=$A9)*('concentration_review'!$F$2:$F$84="油相单体"))),"") | J9: =IFERROR(TEXTJOIN("; ",TRUE,FILTER('concentration_review'!$AA$2:$AA$84,('concentration_review'!$A$2:$A$84=$A9)*('concentration_review'!$G$2:$G$84="油相单体浓度"))),"") | K9: =IFERROR(TEXTJOIN("; ",TRUE,FILTER('concentration_review'!$AB$2:$AB$84,('concentration_review'!$A$2:$A$84=$A9)*('concentration_review'!$G$2:$G$84="油相单体浓度_单位"))),"") | M9: PAN/PET | N9: 1.7 | P9: =IFERROR(TEXTJOIN("; ",TRUE,FILTER('concentration_review'!$Z$2:$Z$84,('concentration_review'!$A$2:$A$84=$A9)*('concentration_review'!$F$2:$F$84="添加剂"))),"") | Q9: =IFERROR(TEXTJOIN("; ",TRUE,FILTER('concentration_review'!$AA$2:$AA$84,('concentration_review'!$A$2:$A$84=$A9)*('concentration_review'!$G$2:$G$84="添加剂浓度"))),"") | R9: =IFERROR(TEXTJOIN("; ",TRUE,FILTER('concentration_review'!$AB$2:$AB$84,('concentration_review'!$A$2:$A$84=$A9)*('concentration_review'!$G$2:$G$84="添加剂浓度_单位"))),"") | S9: '20-30 | T9: min/layer | U9: 20 | V9: °C | AA9: =IFERROR(TEXTJOIN("; ",TRUE,FILTER('concentration_review'!$Z$2:$Z$84,('concentration_review'!$A$2:$A$84=$A9)*('concentration_review'!$F$2:$F$84="改性剂"))),"") | AB9: =IFERROR(TEXTJOIN("; ",TRUE,FILTER('concentration_review'!$AA$2:$AA$84,('concentration_review'!$A$2:$A$84=$A9)*('concentration_review'!$G$2:$G$84="改性剂浓度"))),"") | AC9: =IFERROR(TEXTJOIN("; ",TRUE,FILTER('concentration_review'!$AB$2:$AB$84,('concentration_review'!$A$2:$A$84=$A9)*('concentration_review'!$G$2:$G$84="改性剂浓度_单位"))),"") | AF9: 60 bilayers | AS9: 0.55 | AT9: L/(m²·h) | AU9: 84 | AW9: =IFERROR(TEXTJOIN("; ",TRUE,FILTER('concentration_review'!$AA$2:$AA$84,('concentration_review'!$A$2:$A$84=$A9)*('concentration_review'!$G$2:$G$84="测试NaCl浓度"))),"") | AX9: =IFERROR(TEXTJOIN("; ",TRUE,FILTER('concentration_review'!$AB$2:$AB$84,('concentration_review'!$A$2:$A$84=$A9)*('concentration_review'!$G$2:$G$84="测试NaCl浓度_单位"))),"") | BA9: 5 | BB9: bar | BC9: Stirred | BD9: jin2003.pdf | BE9: 2003 | BF9: 10.1021/la020926f | BG9: NaCl | BH9: NaCl | BI9: 0.11 | BJ9: L/(m²·h·bar) | BK9: 渗透系数(Permeance) | BM9: Use of Polyelectrolyte Layer-by-Layer Assemblies as Nanofiltration and Reverse Osmosis Membranes | BN9: =IFERROR(TEXTJOIN("; ",TRUE,FILTER('concentration_review'!$AC$2:$AC$84,('concentration_review'!$A$2:$A$84=$A9)*('concentration_review'!$C$2:$C$84="aqueous_monomer"))),"") | BO9: =IFERROR(TEXTJOIN("; ",TRUE,FILTER('concentration_review'!$AC$2:$AC$84,('concentration_review'!$A$2:$A$84=$A9)*('concentration_review'!$C$2:$C$84="organic_monomer"))),"") | BP9: =IFERROR(TEXTJOIN("; ",TRUE,FILTER('concentration_review'!$AC$2:$AC$84,('concentration_review'!$A$2:$A$84=$A9)*('concentration_review'!$C$2:$C$84="additive"))),"") | BQ9: =IFERROR(TEXTJOIN("; ",TRUE,FILTER('concentration_review'!$AC$2:$AC$84,('concentration_review'!$A$2:$A$84=$A9)*('concentration_review'!$C$2:$C$84="modifier"))),"") | BR9: =IFERROR(TEXTJOIN("; ",TRUE,FILTER('concentration_review'!$AC$2:$AC$84,('concentration_review'!$A$2:$A$84=$A9)*('concentration_review'!$C$2:$C$84="test_nacl"))),"") | BS9: =SUMPRODUCT((--('concentration_review'!$A$2:$A$84=$A9))*('concentration_review'!$AE$2:$AE$84>0)) | BT9: =IF(=SUMPRODUCT((--('concentration_review'!$A$2:$A$84=$A9))*('concentration_review'!$AE$2:$AE$84>0))>0,1,0)
A10: 8 | B10: RO | C10: Lysozyme-immobilized Polyamide RO membrane | D10: Polyamide | E10: Interfacial polymerization; Surface modification; Enzyme immobilization | F10: =IFERROR(TEXTJOIN("; ",TRUE,FILTER('concentration_review'!$Z$2:$Z$84,('concentration_review'!$A$2:$A$84=$A10)*('concentration_review'!$F$2:$F$84="水相单体"))),"") | G10: =IFERROR(TEXTJOIN("; ",TRUE,FILTER('concentration_review'!$AA$2:$AA$84,('concentration_review'!$A$2:$A$84=$A10)*('concentration_review'!$G$2:$G$84="水相单体浓度"))),"") | H10: =IFERROR(TEXTJOIN("; ",TRUE,FILTER('concentration_review'!$AB$2:$AB$84,('concentration_review'!$A$2:$A$84=$A10)*('concentration_review'!$G$2:$G$84="水相单体浓度_单位"))),"") | I10: =IFERROR(TEXTJOIN("; ",TRUE,FILTER('concentration_review'!$Z$2:$Z$84,('concentration_review'!$A$2:$A$84=$A10)*('concentration_review'!$F$2:$F$84="油相单体"))),"") | J10: =IFERROR(TEXTJOIN("; ",TRUE,FILTER('concentration_review'!$AA$2:$AA$84,('concentration_review'!$A$2:$A$84=$A10)*('concentration_review'!$G$2:$G$84="油相单体浓度"))),"") | K10: =IFERROR(TEXTJOIN("; ",TRUE,FILTER('concentration_review'!$AB$2:$AB$84,('concentration_review'!$A$2:$A$84=$A10)*('concentration_review'!$G$2:$G$84="油相单体浓度_单位"))),"") | L10: n-hexane | M10: Polysulfone | N10: 8 | P10: =IFERROR(TEXTJOIN("; ",TRUE,FILTER('concentration_review'!$Z$2:$Z$84,('concentration_review'!$A$2:$A$84=$A10)*('concentration_review'!$F$2:$F$84="添加剂"))),"") | Q10: =IFERROR(TEXTJOIN("; ",TRUE,FILTER('concentration_review'!$AA$2:$AA$84,('concentration_review'!$A$2:$A$84=$A10)*('concentration_review'!$G$2:$G$84="添加剂浓度"))),"") | R10: =IFERROR(TEXTJOIN("; ",TRUE,FILTER('concentration_review'!$AB$2:$AB$84,('concentration_review'!$A$2:$A$84=$A10)*('concentration_review'!$G$2:$G$84="添加剂浓度_单位"))),"") | S10: 1 | T10: min | U10: 4 | V10: ℃ | W10: 80 | X10: ℃ | Y10: 5 | Z10: min | AA10: =IFERROR(TEXTJOIN("; ",TRUE,FILTER('concentration_review'!$Z$2:$Z$84,('concentration_review'!$A$2:$A$84=$A10)*('concentration_review'!$F$2:$F$84="改性剂"))),"") | AB10: =IFERROR(TEXTJOIN("; ",TRUE,FILTER('concentration_review'!$AA$2:$AA$84,('concentration_review'!$A$2:$A$84=$A10)*('concentration_review'!$G$2:$G$84="改性剂浓度"))),"") | AC10: =IFERROR(TEXTJOIN("; ",TRUE,FILTER('concentration_review'!$AB$2:$AB$84,('concentration_review'!$A$2:$A$84=$A10)*('concentration_review'!$G$2:$G$84="改性剂浓度_单位"))),"") | AD10: 5; 30; 24 | AE10: min; min; h | AO10: 7.5 | AP10: mV | AQ10: 31.3 | AR10: ° | AS10: 0.4 | AT10: m³/(m² day) | AU10: 92 | AV10: % | AW10: =IFERROR(TEXTJOIN("; ",TRUE,FILTER('concentration_review'!$AA$2:$AA$84,('concentration_review'!$A$2:$A$84=$A10)*('concentration_review'!$G$2:$G$84="测试NaCl浓度"))),"") | AX10: =IFERROR(TEXTJOIN("; ",TRUE,FILTER('concentration_review'!$AB$2:$AB$84,('concentration_review'!$A$2:$A$84=$A10)*('concentration_review'!$G$2:$G$84="测试NaCl浓度_单位"))),"") | AY10: 30 | AZ10: % | BA10: 0.75 | BB10: MPa | BC10: Cross-flow | BD10: Saeki et al_2013_Development of antibacterial polyamide reverse osmosis membrane modified with a.pdf | BE10: 2013 | BF10: 10.1016/j.memsci.2012.10.038 | BG10: NaCl | BH10: NaCl | BI10: 0.0533 | BJ10: L/(m²·h·bar) | BK10: 渗透系数(Permeance) | BL10: 60 | BM10: Development of antibacterial polyamide reverse osmosis membrane modified with a covalently immobilized enzyme | BN10: =IFERROR(TEXTJOIN("; ",TRUE,FILTER('concentration_review'!$AC$2:$AC$84,('concentration_review'!$A$2:$A$84=$A10)*('concentration_review'!$C$2:$C$84="aqueous_monomer"))),"") | BO10: =IFERROR(TEXTJOIN("; ",TRUE,FILTER('concentration_review'!$AC$2:$AC$84,('concentration_review'!$A$2:$A$84=$A10)*('concentration_review'!$C$2:$C$84="organic_monomer"))),"") | BP10: =IFERROR(TEXTJOIN("; ",TRUE,FILTER('concentration_review'!$AC$2:$AC$84,('concentration_review'!$A$2:$A$84=$A10)*('concentration_review'!$C$2:$C$84="additive"))),"") | BQ10: =IFERROR(TEXTJOIN("; ",TRUE,FILTER('concentration_review'!$AC$2:$AC$84,('concentration_review'!$A$2:$A$84=$A10)*('concentration_review'!$C$2:$C$84="modifier"))),"") | BR10: =IFERROR(TEXTJOIN("; ",TRUE,FILTER('concentration_review'!$AC$2:$AC$84,('concentration_review'!$A$2:$A$84=$A10)*('concentration_review'!$C$2:$C$84="test_nacl"))),"") | BS10: =SUMPRODUCT((--('concentration_review'!$A$2:$A$84=$A10))*('concentration_review'!$AE$2:$AE$84>0)) | BT10: =IF(=SUMPRODUCT((--('concentration_review'!$A$2:$A$84=$A10))*('concentration_review'!$AE$2:$AE$84>0))>0,1,0)
A11: 9 | B11: RO | C11: 15CC3@RO | D11: Polyamide | E11: Interfacial polymerization (IP) | F11: =IFERROR(TEXTJOIN("; ",TRUE,FILTER('concentration_review'!$Z$2:$Z$84,('concentration_review'!$A$2:$A$84=$A11)*('concentration_review'!$F$2:$F$84="水相单体"))),"") | G11: =IFERROR(TEXTJOIN("; ",TRUE,FILTER('concentration_review'!$AA$2:$AA$84,('concentration_review'!$A$2:$A$84=$A11)*('concentration_review'!$G$2:$G$84="水相单体浓度"))),"") | H11: =IFERROR(TEXTJOIN("; ",TRUE,FILTER('concentration_review'!$AB$2:$AB$84,('concentration_review'!$A$2:$A$84=$A11)*('concentration_review'!$G$2:$G$84="水相单体浓度_单位"))),"") | I11: =IFERROR(TEXTJOIN("; ",TRUE,FILTER('concentration_review'!$Z$2:$Z$84,('concentration_review'!$A$2:$A$84=$A11)*('concentration_review'!$F$2:$F$84="油相单体"))),"") | J11: =IFERROR(TEXTJOIN("; ",TRUE,FILTER('concentration_review'!$AA$2:$AA$84,('concentration_review'!$A$2:$A$84=$A11)*('concentration_review'!$G$2:$G$84="油相单体浓度"))),"") | K11: =IFERROR(TEXTJOIN("; ",TRUE,FILTER('concentration_review'!$AB$2:$AB$84,('concentration_review'!$A$2:$A$84=$A11)*('concentration_review'!$G$2:$G$84="油相单体浓度_单位"))),"") | L11: n-Heptane;Dichloromethane | M11: Polysulfone | P11: =IFERROR(TEXTJOIN("; ",TRUE,FILTER('concentration_review'!$Z$2:$Z$84,('concentration_review'!$A$2:$A$84=$A11)*('concentration_review'!$F$2:$F$84="添加剂"))),"") | Q11: =IFERROR(TEXTJOIN("; ",TRUE,FILTER('concentration_review'!$AA$2:$AA$84,('concentration_review'!$A$2:$A$84=$A11)*('concentration_review'!$G$2:$G$84="添加剂浓度"))),"") | R11: =IFERROR(TEXTJOIN("; ",TRUE,FILTER('concentration_review'!$AB$2:$AB$84,('concentration_review'!$A$2:$A$84=$A11)*('concentration_review'!$G$2:$G$84="添加剂浓度_单位"))),"") | S11: 10 | T11: min | W11: 80 | X11: °C | Y11: 5 | Z11: min | AA11: =IFERROR(TEXTJOIN("; ",TRUE,FILTER('concentration_review'!$Z$2:$Z$84,('concentration_review'!$A$2:$A$84=$A11)*('concentration_review'!$F$2:$F$84="改性剂"))),"") | AB11: =IFERROR(TEXTJOIN("; ",TRUE,FILTER('concentration_review'!$AA$2:$AA$84,('concentration_review'!$A$2:$A$84=$A11)*('concentration_review'!$G$2:$G$84="改性剂浓度"))),"") | AC11: =IFERROR(TEXTJOIN("; ",TRUE,FILTER('concentration_review'!$AB$2:$AB$84,('concentration_review'!$A$2:$A$84=$A11)*('concentration_review'!$G$2:$G$84="改性剂浓度_单位"))),"") | AN11: C=O;N-H;-N=C | AS11: 122.1 | AT11: L/(m²·h) | AU11: 95.97 | AV11: % | AW11: =IFERROR(TEXTJOIN("; ",TRUE,FILTER('concentration_review'!$AA$2:$AA$84,('concentration_review'!$A$2:$A$84=$A11)*('concentration_review'!$G$2:$G$84="测试NaCl浓度"))),"") | AX11: =IFERROR(TEXTJOIN("; ",TRUE,FILTER('concentration_review'!$AB$2:$AB$84,('concentration_review'!$A$2:$A$84=$A11)*('concentration_review'!$G$2:$G$84="测试NaCl浓度_单位"))),"") | BA11: 15.5 | BB11: bar | BC11: Cross-flow | BD11: Yao et al_2025_High performance reverse osmosis membrane with a separation layer consisting of.pdf | BE11: 2025 | BF11: 10.1016/j.desal.2024.118190 | BG11: NaCl | BH11: NaCl | BI11: 7.8774 | BJ11: L/(m²·h·bar) | BK11: 渗透系数(Permeance) | BL11: 600 | BM11: High performance reverse osmosis membrane with a separation layer consisting of highly selective polyamide networks and porous organic cages | BN11: =IFERROR(TEXTJOIN("; ",TRUE,FILTER('concentration_review'!$AC$2:$AC$84,('concentration_review'!$A$2:$A$84=$A11)*('concentration_review'!$C$2:$C$84="aqueous_monomer"))),"") | BO11: =IFERROR(TEXTJOIN("; ",TRUE,FILTER('concentration_review'!$AC$2:$AC$84,('concentration_review'!$A$2:$A$84=$A11)*('concentration_review'!$C$2:$C$84="organic_monomer"))),"") | BP11: =IFERROR(TEXTJOIN("; ",TRUE,FILTER('concentration_review'!$AC$2:$AC$84,('concentration_review'!$A$2:$A$84=$A11)*('concentration_review'!$C$2:$C$84="additive"))),"") | BQ11: =IFERROR(TEXTJOIN("; ",TRUE,FILTER('concentration_review'!$AC$2:$AC$84,('concentration_review'!$A$2:$A$84=$A11)*('concentration_review'!$C$2:$C$84="modifier"))),"") | BR11: =IFERROR(TEXTJOIN("; ",TRUE,FILTER('concentration_review'!$AC$2:$AC$84,('concentration_review'!$A$2:$A$84=$A11)*('concentration_review'!$C$2:$C$84="test_nacl"))),"") | BS11: =SUMPRODUCT((--('concentration_review'!$A$2:$A$84=$A11))*('concentration_review'!$AE$2:$AE$84>0)) | BT11: =IF(=SUMPRODUCT((--('concentration_review'!$A$2:$A$84=$A11))*('concentration_review'!$AE$2:$AE$84>0))>0,1,0)
A12: 10 | B12: RO | C12: TFCM0.5 | D12: Polyamide | E12: Interfacial polymerization (IP) | F12: =IFERROR(TEXTJOIN("; ",TRUE,FILTER('concentration_review'!$Z$2:$Z$84,('concentration_review'!$A$2:$A$84=$A12)*('concentration_review'!$F$2:$F$84="水相单体"))),"") | G12: =IFERROR(TEXTJOIN("; ",TRUE,FILTER('concentration_review'!$AA$2:$AA$84,('concentration_review'!$A$2:$A$84=$A12)*('concentration_review'!$G$2:$G$84="水相单体浓度"))),"") | H12: =IFERROR(TEXTJOIN("; ",TRUE,FILTER('concentration_review'!$AB$2:$AB$84,('concentration_review'!$A$2:$A$84=$A12)*('concentration_review'!$G$2:$G$84="水相单体浓度_单位"))),"") | I12: =IFERROR(TEXTJOIN("; ",TRUE,FILTER('concentration_review'!$Z$2:$Z$84,('concentration_review'!$A$2:$A$84=$A12)*('concentration_review'!$F$2:$F$84="油相单体"))),"") | J12: =IFERROR(TEXTJOIN("; ",TRUE,FILTER('concentration_review'!$AA$2:$AA$84,('concentration_review'!$A$2:$A$84=$A12)*('concentration_review'!$G$2:$G$84="油相单体浓度"))),"") | K12: =IFERROR(TEXTJOIN("; ",TRUE,FILTER('concentration_review'!$AB$2:$AB$84,('concentration_review'!$A$2:$A$84=$A12)*('concentration_review'!$G$2:$G$84="油相单体浓度_单位"))),"") | L12: n-hexane | M12: PSF | P12: =IFERROR(TEXTJOIN("; ",TRUE,FILTER('concentration_review'!$Z$2:$Z$84,('concentration_review'!$A$2:$A$84=$A12)*('concentration_review'!$F$2:$F$84="添加剂"))),"") | Q12: =IFERROR(TEXTJOIN("; ",TRUE,FILTER('concentration_review'!$AA$2:$AA$84,('concentration_review'!$A$2:$A$84=$A12)*('concentration_review'!$G$2:$G$84="添加剂浓度"))),"") | R12: =IFERROR(TEXTJOIN("; ",TRUE,FILTER('concentration_review'!$AB$2:$AB$84,('concentration_review'!$A$2:$A$84=$A12)*('concentration_review'!$G$2:$G$84="添加剂浓度_单位"))),"") | S12: 30 | T12: s | W12: 60 | X12: ℃ | Y12: 2 | Z12: min | AA12: =IFERROR(TEXTJOIN("; ",TRUE,FILTER('concentration_review'!$Z$2:$Z$84,('concentration_review'!$A$2:$A$84=$A12)*('concentration_review'!$F$2:$F$84="改性剂"))),"") | AB12: =IFERROR(TEXTJOIN("; ",TRUE,FILTER('concentration_review'!$AA$2:$AA$84,('concentration_review'!$A$2:$A$84=$A12)*('concentration_review'!$G$2:$G$84="改性剂浓度"))),"") | AC12: =IFERROR(TEXTJOIN("; ",TRUE,FILTER('concentration_review'!$AB$2:$AB$84,('concentration_review'!$A$2:$A$84=$A12)*('concentration_review'!$G$2:$G$84="改性剂浓度_单位"))),"") | AS12: 2 | AT12: L/(m²·h·bar) | AU12: 90 | AV12: % | AW12: =IFERROR(TEXTJOIN("; ",TRUE,FILTER('concentration_review'!$AA$2:$AA$84,('concentration_review'!$A$2:$A$84=$A12)*('concentration_review'!$G$2:$G$84="测试NaCl浓度"))),"") | AX12: =IFERROR(TEXTJOIN("; ",TRUE,FILTER('concentration_review'!$AB$2:$AB$84,('concentration_review'!$A$2:$A$84=$A12)*('concentration_review'!$G$2:$G$84="测试NaCl浓度_单位"))),"") | BA12: 15 | BB12: bar | BC12: Cross-flow | BD12: Fei et al_2022_Imidazole assisted molecular-scale regulation of polyamide for preparing.pdf | BE12: 2022 | BF12: 10.1016/j.jece.2022.108146 | BG12: NaCl | BH12: NaCl | BI12: 0.1333 | BJ12: L/(m²·h·bar) | BK12: 渗透系数(Permeance) | BL12: 30 | BM12: Imidazole assisted molecular-scale regulation of polyamide for preparing reverse osmosis membrane with enhanced water permeance | BN12: =IFERROR(TEXTJOIN("; ",TRUE,FILTER('concentration_review'!$AC$2:$AC$84,('concentration_review'!$A$2:$A$84=$A12)*('concentration_review'!$C$2:$C$84="aqueous_monomer"))),"") | BO12: =IFERROR(TEXTJOIN("; ",TRUE,FILTER('concentration_review'!$AC$2:$AC$84,('concentration_review'!$A$2:$A$84=$A12)*('concentration_review'!$C$2:$C$84="organic_monomer"))),"") | BP12: =IFERROR(TEXTJOIN("; ",TRUE,FILTER('concentration_review'!$AC$2:$AC$84,('concentration_review'!$A$2:$A$84=$A12)*('concentration_review'!$C$2:$C$84="additive"))),"") | BQ12: =IFERROR(TEXTJOIN("; ",TRUE,FILTER('concentration_review'!$AC$2:$AC$84,('concentration_review'!$A$2:$A$84=$A12)*('concentration_review'!$C$2:$C$84="modifier"))),"") | BR12: =IFERROR(TEXTJOIN("; ",TRUE,FILTER('concentration_review'!$AC$2:$AC$84,('concentration_review'!$A$2:$A$84=$A12)*('concentration_review'!$C$2:$C$84="test_nacl"))),"") | BS12: =SUMPRODUCT((--('concentration_review'!$A$2:$A$84=$A12))*('concentration_review'!$AE$2:$AE$84>0)) | BT12: =IF(=SUMPRODUCT((--('concentration_review'!$A$2:$A$84=$A12))*('concentration_review'!$AE$2:$AE$84>0))>0,1,0)
A13: 11 | B13: RO | C13: Filmtec-SW30HR-g-3SBMA | D13: Polyamide; Polysulfobetaine | E13: Interfacial polymerization; ARGET ATRP | F13: =IFERROR(TEXTJOIN("; ",TRUE,FILTER('concentration_review'!$Z$2:$Z$84,('concentration_review'!$A$2:$A$84=$A13)*('concentration_review'!$F$2:$F$84="水相单体"))),"") | G13: =IFERROR(TEXTJOIN("; ",TRUE,FILTER('concentration_review'!$AA$2:$AA$84,('concentration_review'!$A$2:$A$84=$A13)*('concentration_review'!$G$2:$G$84="水相单体浓度"))),"") | H13: =IFERROR(TEXTJOIN("; ",TRUE,FILTER('concentration_review'!$AB$2:$AB$84,('concentration_review'!$A$2:$A$84=$A13)*('concentration_review'!$G$2:$G$84="水相单体浓度_单位"))),"") | I13: =IFERROR(TEXTJOIN("; ",TRUE,FILTER('concentration_review'!$Z$2:$Z$84,('concentration_review'!$A$2:$A$84=$A13)*('concentration_review'!$F$2:$F$84="油相单体"))),"") | J13: =IFERROR(TEXTJOIN("; ",TRUE,FILTER('concentration_review'!$AA$2:$AA$84,('concentration_review'!$A$2:$A$84=$A13)*('concentration_review'!$G$2:$G$84="油相单体浓度"))),"") | K13: =IFERROR(TEXTJOIN("; ",TRUE,FILTER('concentration_review'!$AB$2:$AB$84,('concentration_review'!$A$2:$A$84=$A13)*('concentration_review'!$G$2:$G$84="油相单体浓度_单位"))),"") | L13: Hexane; Methanol/water (1:1 v/v) | M13: Polyester; Polysulfone | P13: =IFERROR(TEXTJOIN("; ",TRUE,FILTER('concentration_review'!$Z$2:$Z$84,('concentration_review'!$A$2:$A$84=$A13)*('concentration_review'!$F$2:$F$84="添加剂"))),"") | Q13: =IFERROR(TEXTJOIN("; ",TRUE,FILTER('concentration_review'!$AA$2:$AA$84,('concentration_review'!$A$2:$A$84=$A13)*('concentration_review'!$G$2:$G$84="添加剂浓度"))),"") | R13: =IFERROR(TEXTJOIN("; ",TRUE,FILTER('concentration_review'!$AB$2:$AB$84,('concentration_review'!$A$2:$A$84=$A13)*('concentration_review'!$G$2:$G$84="添加剂浓度_单位"))),"") | S13: 180; 24 | T13: min (initiator); h (polymerization) | U13: 0 then 20-25 | V13: ℃ | AA13: =IFERROR(TEXTJOIN("; ",TRUE,FILTER('concentration_review'!$Z$2:$Z$84,('concentration_review'!$A$2:$A$84=$A13)*('concentration_review'!$F$2:$F$84="改性剂"))),"") | AB13: =IFERROR(TEXTJOIN("; ",TRUE,FILTER('concentration_review'!$AA$2:$AA$84,('concentration_review'!$A$2:$A$84=$A13)*('concentration_review'!$G$2:$G$84="改性剂浓度"))),"") | AC13: =IFERROR(TEXTJOIN("; ",TRUE,FILTER('concentration_review'!$AB$2:$AB$84,('concentration_review'!$A$2:$A$84=$A13)*('concentration_review'!$G$2:$G$84="改性剂浓度_单位"))),"") | AF13: less than 50 | AG13: nm | AH13: smoother | AN13: sulfonate ions | AS13: 1.14 | AT13: L/(m²·h·bar) | AU13: 96.8 | AV13: % | AW13: =IFERROR(TEXTJOIN("; ",TRUE,FILTER('concentration_review'!$AA$2:$AA$84,('concentration_review'!$A$2:$A$84=$A13)*('concentration_review'!$G$2:$G$84="测试NaCl浓度"))),"") | AX13: =IFERROR(TEXTJOIN("; ",TRUE,FILTER('concentration_review'!$AB$2:$AB$84,('concentration_review'!$A$2:$A$84=$A13)*('concentration_review'!$G$2:$G$84="测试NaCl浓度_单位"))),"") | BA13: 4140 | BB13: kPa | BC13: Cross-flow | BD13: Ginic-Markovic et al_2015_Biofouling resistance of polysulfobetaine coated reverse osmosis membranes.pdf | BE13: 2015 | BF13: 10.1016/j.desal.2015.04.024 | BG13: NaCl | BH13: NaCl | BI13: 0.0003 | BJ13: L/(m²·h·bar) | BK13: 渗透系数(Permeance) | BM13: Biofouling resistance of polysulfobetaine coated reverse osmosis membranes | BN13: =IFERROR(TEXTJOIN("; ",TRUE,FILTER('concentration_review'!$AC$2:$AC$84,('concentration_review'!$A$2:$A$84=$A13)*('concentration_review'!$C$2:$C$84="aqueous_monomer"))),"") | BO13: =IFERROR(TEXTJOIN("; ",TRUE,FILTER('concentration_review'!$AC$2:$AC$84,('concentration_review'!$A$2:$A$84=$A13)*('concentration_review'!$C$2:$C$84="organic_monomer"))),"") | BP13: =IFERROR(TEXTJOIN("; ",TRUE,FILTER('concentration_review'!$AC$2:$AC$84,('concentration_review'!$A$2:$A$84=$A13)*('concentration_review'!$C$2:$C$84="additive"))),"") | BQ13: =IFERROR(TEXTJOIN("; ",TRUE,FILTER('concentration_review'!$AC$2:$AC$84,('concentration_review'!$A$2:$A$84=$A13)*('concentration_review'!$C$2:$C$84="modifier"))),"") | BR13: =IFERROR(TEXTJOIN("; ",TRUE,FILTER('concentration_review'!$AC$2:$AC$84,('concentration_review'!$A$2:$A$84=$A13)*('concentration_review'!$C$2:$C$84="test_nacl"))),"") | BS13: =SUMPRODUCT((--('concentration_review'!$A$2:$A$84=$A13))*('concentration_review'!$AE$2:$AE$84>0)) | BT13: =IF(=SUMPRODUCT((--('concentration_review'!$A$2:$A$84=$A13))*('concentration_review'!$AE$2:$AE$84>0))>0,1,0)
A14: 12 | B14: RO | C14: TFN0.1 | D14: Polyamide | E14: Interfacial polymerization (IP) | F14: =IFERROR(TEXTJOIN("; ",TRUE,FILTER('concentration_review'!$Z$2:$Z$84,('concentration_review'!$A$2:$A$84=$A14)*('concentration_review'!$F$2:$F$84="水相单体"))),"") | G14: =IFERROR(TEXTJOIN("; ",TRUE,FILTER('concentration_review'!$AA$2:$AA$84,('concentration_review'!$A$2:$A$84=$A14)*('concentration_review'!$G$2:$G$84="水相单体浓度"))),"") | H14: =IFERROR(TEXTJOIN("; ",TRUE,FILTER('concentration_review'!$AB$2:$AB$84,('concentration_review'!$A$2:$A$84=$A14)*('concentration_review'!$G$2:$G$84="水相单体浓度_单位"))),"") | I14: =IFERROR(TEXTJOIN("; ",TRUE,FILTER('concentration_review'!$Z$2:$Z$84,('concentration_review'!$A$2:$A$84=$A14)*('concentration_review'!$F$2:$F$84="油相单体"))),"") | J14: =IFERROR(TEXTJOIN("; ",TRUE,FILTER('concentration_review'!$AA$2:$AA$84,('concentration_review'!$A$2:$A$84=$A14)*('concentration_review'!$G$2:$G$84="油相单体浓度"))),"") | K14: =IFERROR(TEXTJOIN("; ",TRUE,FILTER('concentration_review'!$AB$2:$AB$84,('concentration_review'!$A$2:$A$84=$A14)*('concentration_review'!$G$2:$G$84="油相单体浓度_单位"))),"") | L14: Cyclohexane | M14: PSf | P14: =IFERROR(TEXTJOIN("; ",TRUE,FILTER('concentration_review'!$Z$2:$Z$84,('concentration_review'!$A$2:$A$84=$A14)*('concentration_review'!$F$2:$F$84="添加剂"))),"") | Q14: =IFERROR(TEXTJOIN("; ",TRUE,FILTER('concentration_review'!$AA$2:$AA$84,('concentration_review'!$A$2:$A$84=$A14)*('concentration_review'!$G$2:$G$84="添加剂浓度"))),"") | R14: =IFERROR(TEXTJOIN("; ",TRUE,FILTER('concentration_review'!$AB$2:$AB$84,('concentration_review'!$A$2:$A$84=$A14)*('concentration_review'!$G$2:$G$84="添加剂浓度_单位"))),"") | S14: 1 | T14: min | U14: Ambient | W14: 90 | X14: ℃ | Y14: 10 | Z14: min | AA14: =IFERROR(TEXTJOIN("; ",TRUE,FILTER('concentration_review'!$Z$2:$Z$84,('concentration_review'!$A$2:$A$84=$A14)*('concentration_review'!$F$2:$F$84="改性剂"))),"") | AB14: =IFERROR(TEXTJOIN("; ",TRUE,FILTER('concentration_review'!$AA$2:$AA$84,('concentration_review'!$A$2:$A$84=$A14)*('concentration_review'!$G$2:$G$84="改性剂浓度"))),"") | AC14: =IFERROR(TEXTJOIN("; ",TRUE,FILTER('concentration_review'!$AB$2:$AB$84,('concentration_review'!$A$2:$A$84=$A14)*('concentration_review'!$G$2:$G$84="改性剂浓度_单位"))),"") | AF14: 259.25 | AG14: nm | AH14: 75.7 | AI14: nm | AN14: C-N; C=O; Si-O; Al-OH | AQ14: 52.9 | AR14: ° | AS14: 48 | AT14: L m⁻² h⁻¹ | AU14: 80.5 | AV14: % | AW14: =IFERROR(TEXTJOIN("; ",TRUE,FILTER('concentration_review'!$AA$2:$AA$84,('concentration_review'!$A$2:$A$84=$A14)*('concentration_review'!$G$2:$G$84="测试NaCl浓度"))),"") | AX14: =IFERROR(TEXTJOIN("; ",TRUE,FILTER('concentration_review'!$AB$2:$AB$84,('concentration_review'!$A$2:$A$84=$A14)*('concentration_review'!$G$2:$G$84="测试NaCl浓度_单位"))),"") | BA14: 15 | BB14: bar | BC14: Dead-end | BD14: Ghanbari et al_2015_Synthesis and characterization of novel thin film nanocomposite reverse osmosis.pdf | BE14: 2015 | BF14: 10.1039/c4ra16177g | BG14: NaCl | BH14: NaCl | BI14: 3.2 | BJ14: L/(m²·h·bar) | BK14: 渗透系数(Permeance) | BL14: 60 | BM14: Synthesis and characterization of novel thin film nanocomposite reverse osmosis membranes with improved organic fouling properties for water desalination | BN14: =IFERROR(TEXTJOIN("; ",TRUE,FILTER('concentration_review'!$AC$2:$AC$84,('concentration_review'!$A$2:$A$84=$A14)*('concentration_review'!$C$2:$C$84="aqueous_monomer"))),"") | BO14: =IFERROR(TEXTJOIN("; ",TRUE,FILTER('concentration_review'!$AC$2:$AC$84,('concentration_review'!$A$2:$A$84=$A14)*('concentration_review'!$C$2:$C$84="organic_monomer"))),"") | BP14: =IFERROR(TEXTJOIN("; ",TRUE,FILTER('concentration_review'!$AC$2:$AC$84,('concentration_review'!$A$2:$A$84=$A14)*('concentration_review'!$C$2:$C$84="additive"))),"") | BQ14: =IFERROR(TEXTJOIN("; ",TRUE,FILTER('concentration_review'!$AC$2:$AC$84,('concentration_review'!$A$2:$A$84=$A14)*('concentration_review'!$C$2:$C$84="modifier"))),"") | BR14: =IFERROR(TEXTJOIN("; ",TRUE,FILTER('concentration_review'!$AC$2:$AC$84,('concentration_review'!$A$2:$A$84=$A14)*('concentration_review'!$C$2:$C$84="test_nacl"))),"") | BS14: =SUMPRODUCT((--('concentration_review'!$A$2:$A$84=$A14))*('concentration_review'!$AE$2:$AE$84>0)) | BT14: =IF(=SUMPRODUCT((--('concentration_review'!$A$2:$A$84=$A14))*('concentration_review'!$AE$2:$AE$84>0))>0,1,0)
A15: 13 | B15: RO | C15: (0.1:0.013%) N-IPAAm/MBAAm/CA/CTA-RO membrane | D15: Cellulose acetate; Cellulose triacetate; N-isopropylacrylamide; N,N-methylene bisacrylamide | E15: Phase inversion; Grafting; Crosslinking | F15: =IFERROR(TEXTJOIN("; ",TRUE,FILTER('concentration_review'!$Z$2:$Z$84,('concentration_review'!$A$2:$A$84=$A15)*('concentration_review'!$F$2:$F$84="水相单体"))),"") | G15: =IFERROR(TEXTJOIN("; ",TRUE,FILTER('concentration_review'!$AA$2:$AA$84,('concentration_review'!$A$2:$A$84=$A15)*('concentration_review'!$G$2:$G$84="水相单体浓度"))),"") | H15: =IFERROR(TEXTJOIN("; ",TRUE,FILTER('concentration_review'!$AB$2:$AB$84,('concentration_review'!$A$2:$A$84=$A15)*('concentration_review'!$G$2:$G$84="水相单体浓度_单位"))),"") | I15: =IFERROR(TEXTJOIN("; ",TRUE,FILTER('concentration_review'!$Z$2:$Z$84,('concentration_review'!$A$2:$A$84=$A15)*('concentration_review'!$F$2:$F$84="油相单体"))),"") | J15: =IFERROR(TEXTJOIN("; ",TRUE,FILTER('concentration_review'!$AA$2:$AA$84,('concentration_review'!$A$2:$A$84=$A15)*('concentration_review'!$G$2:$G$84="油相单体浓度"))),"") | K15: =IFERROR(TEXTJOIN("; ",TRUE,FILTER('concentration_review'!$AB$2:$AB$84,('concentration_review'!$A$2:$A$84=$A15)*('concentration_review'!$G$2:$G$84="油相单体浓度_单位"))),"") | L15: acetone; acetic acid; dioxane; methanol; ethanol | M15: glass substrate | N15: 7 | P15: =IFERROR(TEXTJOIN("; ",TRUE,FILTER('concentration_review'!$Z$2:$Z$84,('concentration_review'!$A$2:$A$84=$A15)*('concentration_review'!$F$2:$F$84="添加剂"))),"") | Q15: =IFERROR(TEXTJOIN("; ",TRUE,FILTER('concentration_review'!$AA$2:$AA$84,('concentration_review'!$A$2:$A$84=$A15)*('concentration_review'!$G$2:$G$84="添加剂浓度"))),"") | R15: =IFERROR(TEXTJOIN("; ",TRUE,FILTER('concentration_review'!$AB$2:$AB$84,('concentration_review'!$A$2:$A$84=$A15)*('concentration_review'!$G$2:$G$84="添加剂浓度_单位"))),"") | U15: room temperature | W15: 60; 80 | X15: ℃ | Y15: 10; 10 | Z15: min | AA15: =IFERROR(TEXTJOIN("; ",TRUE,FILTER('concentration_review'!$Z$2:$Z$84,('concentration_review'!$A$2:$A$84=$A15)*('concentration_review'!$F$2:$F$84="改性剂"))),"") | AB15: =IFERROR(TEXTJOIN("; ",TRUE,FILTER('concentration_review'!$AA$2:$AA$84,('concentration_review'!$A$2:$A$84=$A15)*('concentration_review'!$G$2:$G$84="改性剂浓度"))),"") | AC15: =IFERROR(TEXTJOIN("; ",TRUE,FILTER('concentration_review'!$AB$2:$AB$84,('concentration_review'!$A$2:$A$84=$A15)*('concentration_review'!$G$2:$G$84="改性剂浓度_单位"))),"") | AD15: 10 | AE15: min | AF15: 250 | AG15: µm | AH15: 13 | AI15: nm | AN15: '-OH; -CH; C=O(acetyl); -NH; C=O(amide); C-N(amide) | AQ15: 43.8 | AR15: ° | AS15: 4.11 | AT15: L/(m²h) | AU15: 90 | AV15: % | AW15: =IFERROR(TEXTJOIN("; ",TRUE,FILTER('concentration_review'!$AA$2:$AA$84,('concentration_review'!$A$2:$A$84=$A15)*('concentration_review'!$G$2:$G$84="测试NaCl浓度"))),"") | AX15: =IFERROR(TEXTJOIN("; ",TRUE,FILTER('concentration_review'!$AB$2:$AB$84,('concentration_review'!$A$2:$A$84=$A15)*('concentration_review'!$G$2:$G$84="测试NaCl浓度_单位"))),"") | BA15: 10 | BB15: bar | BC15: Cross-flow | BD15: 10.1002_pen.25517.pdf | BE15: 2020 | BF15: 10.1002/pen.25517 | BG15: NaCl | BH15: NaCl | BI15: 0.411 | BJ15: L/(m²·h·bar) | BK15: 渗透系数(Permeance) | BM15: Effect of cellulose acetate/cellulose triacetate ratio on reverse osmosis blend membrane performance | BN15: =IFERROR(TEXTJOIN("; ",TRUE,FILTER('concentration_review'!$AC$2:$AC$84,('concentration_review'!$A$2:$A$84=$A15)*('concentration_review'!$C$2:$C$84="aqueous_monomer"))),"") | BO15: =IFERROR(TEXTJOIN("; ",TRUE,FILTER('concentration_review'!$AC$2:$AC$84,('concentration_review'!$A$2:$A$84=$A15)*('concentration_review'!$C$2:$C$84="organic_monomer"))),"") | BP15: =IFERROR(TEXTJOIN("; ",TRUE,FILTER('concentration_review'!$AC$2:$AC$84,('concentration_review'!$A$2:$A$84=$A15)*('concentration_review'!$C$2:$C$84="additive"))),"") | BQ15: =IFERROR(TEXTJOIN("; ",TRUE,FILTER('concentration_review'!$AC$2:$AC$84,('concentration_review'!$A$2:$A$84=$A15)*('concentration_review'!$C$2:$C$84="modifier"))),"") | BR15: =IFERROR(TEXTJOIN("; ",TRUE,FILTER('concentration_review'!$AC$2:$AC$84,('concentration_review'!$A$2:$A$84=$A15)*('concentration_review'!$C$2:$C$84="test_nacl"))),"") | BS15: =SUMPRODUCT((--('concentration_review'!$A$2:$A$84=$A15))*('concentration_review'!$AE$2:$AE$84>0)) | BT15: =IF(=SUMPRODUCT((--('concentration_review'!$A$2:$A$84=$A15))*('concentration_review'!$AE$2:$AE$84>0))>0,1,0)

Sheet concentration_review
A1: __row_index | B1: row_id | C1: slot_name | D1: slot_label_cn | E1: slot_item_index | F1: target_solute_col | G1: target_value_col | H1: target_unit_col | I1: raw_solute | J1: raw_value | K1: raw_unit | L1: parsed_solute | M1: parsed_value | N1: parsed_unit | O1: phase_identified | P1: phase_evidence | Q1: physical_form_inferred | R1: physical_form_evidence | S1: percent_type_inferred | T1: suggested_wtpercent_value | U1: suggested_status | V1: suggested_reason | W1: suggested_final_solute | X1: suggested_final_value | Y1: suggested_final_unit | Z1: final_solute | AA1: final_value | AB1: final_unit | AC1: final_status | AD1: final_reason | AE1: review_flag | AF1: confidence | AG1: need_traceback | AH1: traceback_target
